{"errorMessage":"Lambda process returned error status code: 1. Result: {\"errorType\":\"NullReferenceException\",\"errorMessage\":\"Object reference not set to an instance of an object.\",\"stackTrace\":[\"at Checkout.Payment.Processor.Function.FunctionHandler(SQSEvent evnt, ILambdaContext context) in D:\\\\repo\\\\checkout\\\\Checkout.Payment.Processor\\\\Checkout.Payment.Processor\\\\Function.cs:line 29\",\"at lambda_method(Closure , Stream , Stream , LambdaContextInternal )\"]}. Output:\n\u001b[32mSTART RequestId: 5a145b8a-9326-1ba2-d404-8e99bcf63d90 Version: $LATEST\u001b[0m\nObject reference not set to an instance of an object.: NullReferenceException\n   at Checkout.Payment.Processor.Function.FunctionHandler(SQSEvent evnt, ILambdaContext context) in D:\\repo\\checkout\\Checkout.Payment.Processor\\Checkout.Payment.Processor\\Function.cs:line 29\n   at lambda_method(Closure , Stream , Stream , LambdaContextInternal )\n\n\n\u001b[32mEND RequestId: 5a145b8a-9326-1ba2-d404-8e99bcf63d90\u001b[0m\n\u001b[32mREPORT RequestId: 5a145b8a-9326-1ba2-d404-8e99bcf63d90\tInit Duration: 339.86 ms\tDuration: 97.42 ms\tBilled Duration: 98 ms\tMemory Size: 1536 MB\tMax Memory Used: 64 MB\t\u001b[0m","errorType":"InvocationException","stackTrace":["  File \"/opt/code/localstack/localstack/services/awslambda/lambda_api.py\", line 574, in run_lambda\n    result = LAMBDA_EXECUTOR.execute(func_arn, func_details, event, context=context,\n","  File \"/opt/code/localstack/localstack/services/awslambda/lambda_executors.py\", line 174, in execute\n    return do_execute()\n","  File \"/opt/code/localstack/localstack/services/awslambda/lambda_executors.py\", line 166, in do_execute\n    return _run(func_arn=func_arn)\n","  File \"/opt/code/localstack/localstack/utils/cloudwatch/cloudwatch_util.py\", line 149, in wrapped\n    raise e\n","  File \"/opt/code/localstack/localstack/utils/cloudwatch/cloudwatch_util.py\", line 145, in wrapped\n    result = func(*args, **kwargs)\n","  File \"/opt/code/localstack/localstack/services/awslambda/lambda_executors.py\", line 157, in _run\n    raise e\n","  File \"/opt/code/localstack/localstack/services/awslambda/lambda_executors.py\", line 145, in _run\n    result = self._execute(func_arn, func_details, event, context, version)\n","  File \"/opt/code/localstack/localstack/services/awslambda/lambda_executors.py\", line 323, in _execute\n    result = self.run_lambda_executor(cmd, stdin, env_vars=environment, func_details=func_details)\n","  File \"/opt/code/localstack/localstack/services/awslambda/lambda_executors.py\", line 229, in run_lambda_executor\n    raise InvocationException('Lambda process returned error status code: %s. Result: %s. Output:\\n%s' %\n"]}
